---
layout: post
title:  "Play2.3(Java)・MySQL5.6でCaused by: java.sql.SQLException: Connection is closed!が出たとき"
date:   2016-09-25 13:09:43 +0900
categories: Development
---

Play2.3(Java)で下記のようなエラーが出て解決するまでの経緯。
MySQLは5.6です。

```
@6pp2cmieh: Execution exception in null:null
        at play.api.Application$class.handleError(Application.scala:296)
        at play.api.DefaultApplication.handleError(Application.scala:402)
        at play.core.server.netty.PlayDefaultUpstreamHandler$$anonfun$3$$anonfun$applyOrElse$4.apply(PlayDefaultUpstreamHandler.scala:320)
        at play.core.server.netty.PlayDefaultUpstreamHandler$$anonfun$3$$anonfun$applyOrElse$4.apply(PlayDefaultUpstreamHandler.scala:320)
        at scala.Option.map(Option.scala:146)
        at play.core.server.netty.PlayDefaultUpstreamHandler$$anonfun$3.applyOrElse(PlayDefaultUpstreamHandler.scala:320)
        at play.core.server.netty.PlayDefaultUpstreamHandler$$anonfun$3.applyOrElse(PlayDefaultUpstreamHandler.scala:316)
        at scala.concurrent.Future$$anonfun$recoverWith$1.apply(Future.scala:344)
        at scala.concurrent.Future$$anonfun$recoverWith$1.apply(Future.scala:343)
        at scala.concurrent.impl.CallbackRunnable.run(Promise.scala:32)
        at play.api.libs.iteratee.Execution$trampoline$.execute(Execution.scala:46)
        at scala.concurrent.impl.CallbackRunnable.executeWithValue(Promise.scala:40)
        at scala.concurrent.impl.Promise$DefaultPromise.tryComplete(Promise.scala:248)
        at scala.concurrent.Promise$class.complete(Promise.scala:55)
        at scala.concurrent.impl.Promise$DefaultPromise.complete(Promise.scala:153)
        at scala.concurrent.impl.Future$PromiseCompletingRunnable.run(Future.scala:23)
        at akka.dispatch.TaskInvocation.run(AbstractDispatcher.scala:41)
        at akka.dispatch.ForkJoinExecutorConfigurator$AkkaForkJoinTask.exec(AbstractDispatcher.scala:393)
        at scala.concurrent.forkjoin.ForkJoinTask.doExec(ForkJoinTask.java:260)
        at scala.concurrent.forkjoin.ForkJoinPool$WorkQueue.runTask(ForkJoinPool.java:1339)
        at scala.concurrent.forkjoin.ForkJoinPool.runWorker(ForkJoinPool.java:1979)
        at scala.concurrent.forkjoin.ForkJoinWorkerThread.run(ForkJoinWorkerThread.java:107)
Caused by: javax.persistence.PersistenceException: java.sql.SQLException: Connection is closed!
        at com.avaje.ebeaninternal.server.transaction.JdbcTransaction.rollback(JdbcTransaction.java:640)
        at com.avaje.ebeaninternal.server.transaction.JdbcTransaction.rollback(JdbcTransaction.java:625)
        at com.avaje.ebeaninternal.server.transaction.TransactionMap$State.rollback(TransactionMap.java:96)
        at com.avaje.ebeaninternal.server.transaction.DefaultTransactionThreadLocal.rollback(DefaultTransactionThreadLocal.java:89)
        at com.avaje.ebeaninternal.server.transaction.DefaultTransactionScopeManager.rollback(DefaultTransactionScopeManager.java:37)
        at com.avaje.ebeaninternal.server.core.DefaultServer.rollbackTransaction(DefaultServer.java:884)
        at helper.TransactionHelper.rollbackTransaction(TransactionHelper.java:99)
        at filter.BatchGlobalSettings$SessionAction.call(BatchGlobalSettings.java:111)
        at play.core.j.JavaAction$$anonfun$11.apply(JavaAction.scala:82)
        at play.core.j.JavaAction$$anonfun$11.apply(JavaAction.scala:82)
        at scala.concurrent.impl.Future$PromiseCompletingRunnable.liftedTree1$1(Future.scala:24)
        at scala.concurrent.impl.Future$PromiseCompletingRunnable.run(Future.scala:24)
        at play.core.j.HttpExecutionContext$$anon$2.run(HttpExecutionContext.scala:40)
        at play.api.libs.iteratee.Execution$trampoline$.execute(Execution.scala:46)
        at play.core.j.HttpExecutionContext.execute(HttpExecutionContext.scala:32)
        at scala.concurrent.impl.Future$.apply(Future.scala:31)
        at scala.concurrent.Future$.apply(Future.scala:492)
        at play.core.j.JavaAction$class.apply(JavaAction.scala:82)
        at play.core.Router$HandlerInvokerFactory$JavaActionInvokerFactory$$anon$15$$anon$1.apply(Router.scala:252)
        at play.api.mvc.Action$$anonfun$apply$1$$anonfun$apply$4$$anonfun$apply$5.apply(Action.scala:130)
        at play.api.mvc.Action$$anonfun$apply$1$$anonfun$apply$4$$anonfun$apply$5.apply(Action.scala:130)
        at play.utils.Threads$.withContextClassLoader(Threads.scala:21)
        at play.api.mvc.Action$$anonfun$apply$1$$anonfun$apply$4.apply(Action.scala:129)
        at play.api.mvc.Action$$anonfun$apply$1$$anonfun$apply$4.apply(Action.scala:128)
        at scala.Option.map(Option.scala:146)
        at play.api.mvc.Action$$anonfun$apply$1.apply(Action.scala:128)
        at play.api.mvc.Action$$anonfun$apply$1.apply(Action.scala:121)
        at play.api.libs.iteratee.Iteratee$$anonfun$mapM$1.apply(Iteratee.scala:483)
        at play.api.libs.iteratee.Iteratee$$anonfun$mapM$1.apply(Iteratee.scala:483)
        at play.api.libs.iteratee.Iteratee$$anonfun$flatMapM$1.apply(Iteratee.scala:519)
        at play.api.libs.iteratee.Iteratee$$anonfun$flatMapM$1.apply(Iteratee.scala:519)
        at play.api.libs.iteratee.Iteratee$$anonfun$flatMap$1$$anonfun$apply$14.apply(Iteratee.scala:496)
        at play.api.libs.iteratee.Iteratee$$anonfun$flatMap$1$$anonfun$apply$14.apply(Iteratee.scala:496)
        at scala.concurrent.impl.Future$PromiseCompletingRunnable.liftedTree1$1(Future.scala:24)
        at scala.concurrent.impl.Future$PromiseCompletingRunnable.run(Future.scala:24)
        ... 6 more
Caused by: java.sql.SQLException: Connection is closed!
        at com.jolbox.bonecp.ConnectionHandle.checkClosed(ConnectionHandle.java:459)
        at com.jolbox.bonecp.ConnectionHandle.rollback(ConnectionHandle.java:1270)
        at com.avaje.ebeaninternal.server.transaction.JdbcTransaction.rollback(JdbcTransaction.java:637)
        ... 40 more
```

## Caused by: java.sql.SQLException: Connection is closed!

まずはこちらの

`Caused by: java.sql.SQLException: Connection is closed!`でググってみると
色々出てきますがどれも今回のエラーと直結するようなものはありませんでした。

実際にどのSQLが走った時にエラーがでるのか調べるためSQLのログを出力するように設定してみました。

[http://qiita.com/ispern/items/d49ac839063a122e7c67](http://qiita.com/ispern/items/d49ac839063a122e7c67)

実際に落ちているSQLをみると、テキストに絵文字が含まれていました。

なので、対象のカラムを絵文字を許容するように変更致しました。

```
ALTER TABLE `hoge`
CHANGE COLUMN `fuga` `fuga` VARCHAR(5000) CHARACTER SET 'utf8mb4' NULL DEFAULT NULL COMMENT 'hogehoge' ;
```

これで`Caused by: java.sql.SQLException: Connection is closed!`のエラーはでなくなり一見落着。

他の原因でも起きるので、デバッグしながら原因を探るのが良さそうですね。
